<?xml version='1.0'?>
<sdf version="1.6">
  <model name="drone1">
    <pose>0 0 0.194923 0 0 0</pose>
        <link name='base_link'>
          <velocity_decay>
            <linear>0.0</linear>
            <angular>0.0</angular>
          </velocity_decay>
          <inertial>
            <pose>0 0 0 0 0 0</pose>
            <mass>1.5</mass>
            <inertia>
              <ixx>0.008</ixx>
              <ixy>0</ixy>
              <ixz>0</ixz>
              <iyy>0.015</iyy>
              <iyz>0</iyz>
              <izz>0.017</izz>
            </inertia>
          </inertial>
          <collision name='base_link_collision'>
            <pose>0 0 -0.08 0 0 0</pose>
            <geometry>
              <box>
                <size>0.47 0.47 0.23</size>
              </box>
            </geometry>
            <surface>
              <contact>
                <ode>
                  <max_vel>100.0</max_vel>
                  <min_depth>0.001</min_depth>
                </ode>
              </contact>
              <friction>
                <ode>
                  <mu>1.0</mu>
                  <mu2>1.0</mu2>
                </ode>
              </friction>
            </surface>
          </collision>
          <visual name='base_link_visual'>
            <geometry>
              <mesh>
                <uri>model://iris_with_standoffs/meshes/iris.dae</uri>
              </mesh>
            </geometry>
            <material>
              <script>
                <name>Gazebo/DarkGrey</name>
              </script>
            </material>
          </visual>

          <visual name='front_left_leg_visual'>
            <pose>0.123 0.22 -0.11 0 0 0</pose>
            <geometry>
              <cylinder>
                <radius>0.005</radius>
                <length>0.17</length>
              </cylinder>
            </geometry>
            <material>
              <script>
                <name>Gazebo/FlatBlack</name>
                <uri>file://media/materials/scripts/gazebo.material</uri>
              </script>
            </material>
          </visual>
          <visual name='front_right_leg_visual'>
            <pose>0.123 -0.22 -0.11 0 0 0</pose>
            <geometry>
              <cylinder>
                <radius>0.005</radius>
                <length>0.17</length>
              </cylinder>
            </geometry>
            <material>
              <script>
                <name>Gazebo/FlatBlack</name>
                <uri>file://media/materials/scripts/gazebo.material</uri>
              </script>
            </material>
          </visual>
          <visual name='rear_left_leg_visual'>
            <pose>-0.140 0.21 -0.11 0 0 0</pose>
            <geometry>
              <cylinder>
                <radius>0.005</radius>
                <length>0.17</length>
              </cylinder>
            </geometry>
            <material>
              <script>
                <name>Gazebo/FlatBlack</name>
                <uri>file://media/materials/scripts/gazebo.material</uri>
              </script>
            </material>
          </visual>
          <visual name='rear_right_leg_visual'>
            <pose>-0.140 -0.21 -0.11 0 0 0</pose>
            <geometry>
              <cylinder>
                <radius>0.005</radius>
                <length>0.17</length>
              </cylinder>
            </geometry>
            <material>
              <script>
                <name>Gazebo/FlatBlack</name>
                <uri>file://media/materials/scripts/gazebo.material</uri>
              </script>
            </material>
          </visual>
          <!--sensor type="camera" name="camera">
            <pose>0 0 -0.1 0 1.57079632679 0</pose>
            <visualize>true</visualize>
            <update_rate>1.0</update_rate>
            <camera name="head">
                <horizontal_fov>1.0123</horizontal_fov>
                <image>
                    <width>320</width>
                    <height>240</height>
                    <format>B8G8R8</format>
                </image>
                <clip>
                    <near>0.02</near>
                    <far>300</far>
                </clip>
            </camera>
            <plugin name="camera_controller" filename="libgazebo_ros_camera.so">
                <alwaysOn>true</alwaysOn>
                <updateRate>0.0</updateRate>
                <cameraName>/drone1/camera</cameraName>
                <imageTopicName>/drone1/camera/images</imageTopicName>
                <cameraInfoTopicName>/drone1/camera/info</cameraInfoTopicName>
                <frameName>camera_link</frameName>
                <hackBaseline>0.1</hackBaseline>
                <distortionK1>0.0</distortionK1>
                <distortionK2>0.0</distortionK2>
                <distortionK3>0.0</distortionK3>
                <distortionT1>0.0</distortionT1>
                <distortionT2>0.0</distortionT2>
                <CxPrime>0.0</CxPrime>
                <Cx>0.0</Cx>
                <Cy>0.0</Cy>
                <focalLength>0.0</focalLength>
            </plugin>
        </sensor-->
        </link>
        <link name='iris/ground_truth/odometry_sensorgt_link'>
          <pose>0 0 0 0 -0 0</pose>
          <inertial>
            <pose>0 0 0 0 -0 0</pose>
            <mass>0.15</mass>
            <inertia>
              <ixx>0.0001</ixx>
              <ixy>0</ixy>
              <ixz>0</ixz>
              <iyy>0.0002</iyy>
              <iyz>0</iyz>
              <izz>0.0002</izz>
            </inertia>
          </inertial>
        </link>
        <joint name='iris/ground_truth/odometry_sensorgt_joint' type='revolute'>
          <child>iris/ground_truth/odometry_sensorgt_link</child>
          <parent>base_link</parent>
          <axis>
            <xyz>0 0 1</xyz>
            <limit>
              <lower>0</lower>
              <upper>0</upper>
              <effort>0</effort>
              <velocity>0</velocity>
            </limit>
            <dynamics>
              <damping>1.0</damping>
            </dynamics>
            <use_parent_model_frame>1</use_parent_model_frame>
          </axis>
          <physics>
            <ode>
              <implicit_spring_damper>1</implicit_spring_damper>
            </ode>
          </physics>
        </joint>
        <link name='iris/imu_link'>
          <inertial>
            <pose>0 0 0 0 0 0</pose>
            <mass>0.15</mass>
            <inertia>
              <ixx>0.00001</ixx>
              <ixy>0</ixy>
              <ixz>0</ixz>
              <iyy>0.00002</iyy>
              <iyz>0</iyz>
              <izz>0.00002</izz>
            </inertia>
          </inertial>
          <sensor name="imu_sensor" type="imu">
            <pose>0 0 0 3.141593 0 0</pose>
            <always_on>1</always_on>
            <update_rate>1000.0</update_rate>
          </sensor>
        </link>
        <joint name='iris/imu_joint' type='revolute'>
          <child>iris/imu_link</child>
          <parent>base_link</parent>
          <axis>
            <xyz>0 0 1</xyz>
            <limit>
              <lower>0</lower>
              <upper>0</upper>
              <effort>0</effort>
              <velocity>0</velocity>
            </limit>
            <dynamics>
              <damping>1.0</damping>
            </dynamics>
            <use_parent_model_frame>1</use_parent_model_frame>
          </axis>
          <physics>
            <ode>
              <implicit_spring_damper>1</implicit_spring_damper>
            </ode>
          </physics>
        </joint>
    <!--
        <link name='iris/imugt_link'>
          <pose>0 0 0 0 -0 0</pose>
          <inertial>
            <pose>0 0 0 0 -0 0</pose>
            <mass>1e-02</mass>
            <inertia>
              <ixx>0.0002</ixx>
              <ixy>0</ixy>
              <ixz>0</ixz>
              <iyy>0.0002</iyy>
              <iyz>0</iyz>
              <izz>0.0002</izz>
            </inertia>
          </inertial>
        </link>
        <joint name='iris/imugt_joint' type='revolute'>
          <child>iris/imugt_link</child>
          <parent>base_link</parent>
          <axis>
            <xyz>0 0 1</xyz>
            <limit>
              <lower>0</lower>
              <upper>0</upper>
              <effort>0</effort>
              <velocity>0</velocity>
            </limit>
            <dynamics>
              <spring_reference>0</spring_reference>
              <spring_stiffness>0</spring_stiffness>
            </dynamics>
            <use_parent_model_frame>1</use_parent_model_frame>
          </axis>
        </joint>
    -->
        <link name='rotor_0'>
          <pose>0.13 -0.22 0.023 0 -0 0</pose>
          <inertial>
            <pose>0 0 0 0 -0 0</pose>
            <mass>0.025</mass>
            <inertia>
              <ixx>9.75e-06</ixx>
              <ixy>0</ixy>
              <ixz>0</ixz>
              <iyy>0.000166704</iyy>
              <iyz>0</iyz>
              <izz>0.000167604</izz>
            </inertia>
          </inertial>
          <collision name='rotor_0_collision'>
            <pose>0 0 0 0 -0 0</pose>
            <geometry>
              <cylinder>
                <length>0.005</length>
                <radius>0.1</radius>
              </cylinder>
            </geometry>
            <surface>
              <contact>
                <ode/>
              </contact>
              <friction>
                <ode/>
              </friction>
            </surface>
          </collision>
          <visual name='rotor_0_visual'>
            <pose>0 0 0 0 -0 0</pose>
            <geometry>
              <mesh>
                <scale>1 1 1</scale>
                <uri>model://iris_with_standoffs/meshes/iris_prop_ccw.dae</uri>
              </mesh>
            </geometry>
            <material>
              <script>
                <name>Gazebo/Blue</name>
                <uri>__default__</uri>
              </script>
            </material>
          </visual>
          <gravity>1</gravity>
          <velocity_decay/>
          <self_collide>0</self_collide>
        </link>
        <joint name='rotor_0_joint' type='revolute'>
          <child>rotor_0</child>
          <parent>base_link</parent>
          <axis>
            <xyz>0 0 1</xyz>
            <limit>
              <lower>-1e+16</lower>
              <upper>1e+16</upper>
            </limit>
            <dynamics>
              <damping>0.004</damping>
            </dynamics>
            <use_parent_model_frame>1</use_parent_model_frame>
          </axis>
          <physics>
            <ode>
              <implicit_spring_damper>1</implicit_spring_damper>
            </ode>
          </physics>
        </joint>
        <link name='rotor_1'>
          <pose>-0.13 0.2 0.023 0 -0 0</pose>
          <inertial>
            <pose>0 0 0 0 -0 0</pose>
            <mass>0.025</mass>
            <inertia>
              <ixx>9.75e-06</ixx>
              <ixy>0</ixy>
              <ixz>0</ixz>
              <iyy>0.000166704</iyy>
              <iyz>0</iyz>
              <izz>0.000167604</izz>
            </inertia>
          </inertial>
          <collision name='rotor_1_collision'>
            <pose>0 0 0 0 -0 0</pose>
            <geometry>
              <cylinder>
                <length>0.005</length>
                <radius>0.1</radius>
              </cylinder>
            </geometry>
            <surface>
              <contact>
                <ode/>
              </contact>
              <friction>
                <ode/>
              </friction>
            </surface>
          </collision>
          <visual name='rotor_1_visual'>
            <pose>0 0 0 0 -0 0</pose>
            <geometry>
              <mesh>
                <scale>1 1 1</scale>
                <uri>model://iris_with_standoffs/meshes/iris_prop_ccw.dae</uri>
              </mesh>
            </geometry>
            <material>
              <script>
                <name>Gazebo/DarkGrey</name>
                <uri>__default__</uri>
              </script>
            </material>
          </visual>
          <gravity>1</gravity>
          <velocity_decay/>
          <self_collide>0</self_collide>
        </link>
        <joint name='rotor_1_joint' type='revolute'>
          <child>rotor_1</child>
          <parent>base_link</parent>
          <axis>
            <xyz>0 0 1</xyz>
            <limit>
              <lower>-1e+16</lower>
              <upper>1e+16</upper>
            </limit>
            <dynamics>
              <damping>0.004</damping>
            </dynamics>
            <use_parent_model_frame>1</use_parent_model_frame>
          </axis>
          <physics>
            <ode>
              <implicit_spring_damper>1</implicit_spring_damper>
            </ode>
          </physics>
        </joint>
        <link name='rotor_2'>
          <pose>0.13 0.22 0.023 0 -0 0</pose>
          <inertial>
            <pose>0 0 0 0 -0 0</pose>
            <mass>0.025</mass>
            <inertia>
              <ixx>9.75e-06</ixx>
              <ixy>0</ixy>
              <ixz>0</ixz>
              <iyy>0.000166704</iyy>
              <iyz>0</iyz>
              <izz>0.000167604</izz>
            </inertia>
          </inertial>
          <collision name='rotor_2_collision'>
            <pose>0 0 0 0 -0 0</pose>
            <geometry>
              <cylinder>
                <length>0.005</length>
                <radius>0.1</radius>
              </cylinder>
            </geometry>
            <surface>
              <contact>
                <ode/>
              </contact>
              <friction>
                <ode/>
              </friction>
            </surface>
          </collision>
          <visual name='rotor_2_visual'>
            <pose>0 0 0 0 -0 0</pose>
            <geometry>
              <mesh>
                <scale>1 1 1</scale>
                <uri>model://iris_with_standoffs/meshes/iris_prop_cw.dae</uri>
              </mesh>
            </geometry>
            <material>
              <script>
                <name>Gazebo/Blue</name>
                <uri>__default__</uri>
              </script>
            </material>
          </visual>
          <gravity>1</gravity>
          <velocity_decay/>
          <self_collide>0</self_collide>
        </link>
        <joint name='rotor_2_joint' type='revolute'>
          <child>rotor_2</child>
          <parent>base_link</parent>
          <axis>
            <xyz>0 0 1</xyz>
            <limit>
              <lower>-1e+16</lower>
              <upper>1e+16</upper>
            </limit>
            <dynamics>
              <damping>0.004</damping>
            </dynamics>
            <use_parent_model_frame>1</use_parent_model_frame>
          </axis>
          <physics>
            <ode>
              <implicit_spring_damper>1</implicit_spring_damper>
            </ode>
          </physics>
        </joint>
        <link name='rotor_3'>
          <pose>-0.13 -0.2 0.023 0 -0 0</pose>
          <inertial>
            <pose>0 0 0 0 -0 0</pose>
            <mass>0.025</mass>
            <inertia>
              <ixx>9.75e-06</ixx>
              <ixy>0</ixy>
              <ixz>0</ixz>
              <iyy>0.000166704</iyy>
              <iyz>0</iyz>
              <izz>0.000167604</izz>
            </inertia>
          </inertial>
          <collision name='rotor_3_collision'>
            <pose>0 0 0 0 -0 0</pose>
            <geometry>
              <cylinder>
                <length>0.005</length>
                <radius>0.1</radius>
              </cylinder>
            </geometry>
            <surface>
              <contact>
                <ode/>
              </contact>
              <friction>
                <ode/>
              </friction>
            </surface>
          </collision>
          <visual name='rotor_3_visual'>
            <pose>0 0 0 0 -0 0</pose>
            <geometry>
              <mesh>
                <scale>1 1 1</scale>
                <uri>model://iris_with_standoffs/meshes/iris_prop_cw.dae</uri>
              </mesh>
            </geometry>
            <material>
              <script>
                <name>Gazebo/DarkGrey</name>
                <uri>__default__</uri>
              </script>
            </material>
          </visual>
          <gravity>1</gravity>
          <velocity_decay/>
          <self_collide>0</self_collide>
        </link>
        <joint name='rotor_3_joint' type='revolute'>
          <child>rotor_3</child>
          <parent>base_link</parent>
          <axis>
            <xyz>0 0 1</xyz>
            <limit>
              <lower>-1e+16</lower>
              <upper>1e+16</upper>
            </limit>
            <dynamics>
              <damping>0.004</damping>
            </dynamics>
            <use_parent_model_frame>1</use_parent_model_frame>
          </axis>
          <physics>
            <ode>
              <implicit_spring_damper>1</implicit_spring_damper>
            </ode>
          </physics>
        </joint>
        <static>0</static>

    <!-- plugins -->
    <plugin name="rotor_0_blade_1" filename="libLiftDragPlugin.so">
      <a0>0.3</a0>
      <alpha_stall>1.4</alpha_stall>
      <cla>4.2500</cla>
      <cda>0.10</cda>
      <cma>0.00</cma>
      <cla_stall>-0.025</cla_stall>
      <cda_stall>0.0</cda_stall>
      <cma_stall>0.0</cma_stall>
      <area>0.002</area>
      <air_density>1.2041</air_density>
      <cp>0.084 0 0</cp>
      <forward>0 1 0</forward>
      <upward>0 0 1</upward>
      <link_name>rotor_0</link_name>
    </plugin>
    <plugin name="rotor_0_blade_2" filename="libLiftDragPlugin.so">
      <a0>0.3</a0>
      <alpha_stall>1.4</alpha_stall>
      <cla>4.2500</cla>
      <cda>0.10</cda>
      <cma>0.00</cma>
      <cla_stall>-0.025</cla_stall>
      <cda_stall>0.0</cda_stall>
      <cma_stall>0.0</cma_stall>
      <area>0.002</area>
      <air_density>1.2041</air_density>
      <cp>-0.084 0 0</cp>
      <forward>0 -1 0</forward>
      <upward>0 0 1</upward>
      <link_name>rotor_0</link_name>
    </plugin>

    <plugin name="rotor_1_blade_1" filename="libLiftDragPlugin.so">
      <a0>0.3</a0>
      <alpha_stall>1.4</alpha_stall>
      <cla>4.2500</cla>
      <cda>0.10</cda>
      <cma>0.00</cma>
      <cla_stall>-0.025</cla_stall>
      <cda_stall>0.0</cda_stall>
      <cma_stall>0.0</cma_stall>
      <area>0.002</area>
      <air_density>1.2041</air_density>
      <cp>0.084 0 0</cp>
      <forward>0 1 0</forward>
      <upward>0 0 1</upward>
      <link_name>rotor_1</link_name>
    </plugin>
    <plugin name="rotor_1_blade_2" filename="libLiftDragPlugin.so">
      <a0>0.3</a0>
      <alpha_stall>1.4</alpha_stall>
      <cla>4.2500</cla>
      <cda>0.10</cda>
      <cma>0.00</cma>
      <cla_stall>-0.025</cla_stall>
      <cda_stall>0.0</cda_stall>
      <cma_stall>0.0</cma_stall>
      <area>0.002</area>
      <air_density>1.2041</air_density>
      <cp>-0.084 0 0</cp>
      <forward>0 -1 0</forward>
      <upward>0 0 1</upward>
      <link_name>rotor_1</link_name>
    </plugin>

    <plugin name="rotor_2_blade_1" filename="libLiftDragPlugin.so">
      <a0>0.3</a0>
      <alpha_stall>1.4</alpha_stall>
      <cla>4.2500</cla>
      <cda>0.10</cda>
      <cma>0.00</cma>
      <cla_stall>-0.025</cla_stall>
      <cda_stall>0.0</cda_stall>
      <cma_stall>0.0</cma_stall>
      <area>0.002</area>
      <air_density>1.2041</air_density>
      <cp>0.084 0 0</cp>
      <forward>0 -1 0</forward>
      <upward>0 0 1</upward>
      <link_name>rotor_2</link_name>
    </plugin>
    <plugin name="rotor_2_blade_2" filename="libLiftDragPlugin.so">
      <a0>0.3</a0>
      <alpha_stall>1.4</alpha_stall>
      <cla>4.2500</cla>
      <cda>0.10</cda>
      <cma>0.00</cma>
      <cla_stall>-0.025</cla_stall>
      <cda_stall>0.0</cda_stall>
      <cma_stall>0.0</cma_stall>
      <area>0.002</area>
      <air_density>1.2041</air_density>
      <cp>-0.084 0 0</cp>
      <forward>0 1 0</forward>
      <upward>0 0 1</upward>
      <link_name>rotor_2</link_name>
    </plugin>

    <plugin name="rotor_3_blade_1" filename="libLiftDragPlugin.so">
      <a0>0.3</a0>
      <alpha_stall>1.4</alpha_stall>
      <cla>4.2500</cla>
      <cda>0.10</cda>
      <cma>0.00</cma>
      <cla_stall>-0.025</cla_stall>
      <cda_stall>0.0</cda_stall>
      <cma_stall>0.0</cma_stall>
      <area>0.002</area>
      <air_density>1.2041</air_density>
      <cp>0.084 0 0</cp>
      <forward>0 -1 0</forward>
      <upward>0 0 1</upward>
      <link_name>rotor_3</link_name>
    </plugin>
    <plugin name="rotor_3_blade_2" filename="libLiftDragPlugin.so">
      <a0>0.3</a0>
      <alpha_stall>1.4</alpha_stall>
      <cla>4.2500</cla>
      <cda>0.10</cda>
      <cma>0.00</cma>
      <cla_stall>-0.025</cla_stall>
      <cda_stall>0.0</cda_stall>
      <cma_stall>0.0</cma_stall>
      <area>0.002</area>
      <air_density>1.2041</air_density>
      <cp>-0.084 0 0</cp>
      <forward>0 1 0</forward>
      <upward>0 0 1</upward>
      <link_name>rotor_3</link_name>
    </plugin>
    <plugin name="arducopter_plugin" filename="libArduPilotPlugin.so">
      <fdm_addr>127.0.0.1</fdm_addr>
      <fdm_port_in>9002</fdm_port_in>
      <fdm_port_out>9003</fdm_port_out>
      <!--
          Require by APM :
          Only change model and gazebo from XYZ to XY-Z coordinates
      -->
      <modelXYZToAirplaneXForwardZDown>0 0 0 3.141593 0 0</modelXYZToAirplaneXForwardZDown>
      <gazeboXYZToNED>0 0 0 3.141593 0 0</gazeboXYZToNED>
      <imuName>drone1::iris/imu_link::imu_sensor</imuName>
      <connectionTimeoutMaxCount>5</connectionTimeoutMaxCount>
      <control channel="0">
      <!--
          incoming control command [0, 1]
          so offset it by 0 to get [0, 1]
          and divide max target by 1.
          offset = 0
          multiplier = 838 max rpm / 1 = 838
        -->
        <type>VELOCITY</type>
        <offset>0</offset>
        <p_gain>0.20</p_gain>
        <i_gain>0</i_gain>
        <d_gain>0</d_gain>
        <i_max>0</i_max>
        <i_min>0</i_min>
        <cmd_max>2.5</cmd_max>
        <cmd_min>-2.5</cmd_min>
        <jointName>rotor_0_joint</jointName>
        <multiplier>838</multiplier>
        <controlVelocitySlowdownSim>1</controlVelocitySlowdownSim>
      </control>
      <control channel="1">
        <type>VELOCITY</type>
        <offset>0</offset>
        <p_gain>0.20</p_gain>
        <i_gain>0</i_gain>
        <d_gain>0</d_gain>
        <i_max>0</i_max>
        <i_min>0</i_min>
        <cmd_max>2.5</cmd_max>
        <cmd_min>-2.5</cmd_min>
        <jointName>rotor_1_joint</jointName>
        <multiplier>838</multiplier>
        <controlVelocitySlowdownSim>1</controlVelocitySlowdownSim>
      </control>
      <control channel="2">
        <type>VELOCITY</type>
        <offset>0</offset>
        <p_gain>0.20</p_gain>
        <i_gain>0</i_gain>
        <d_gain>0</d_gain>
        <i_max>0</i_max>
        <i_min>0</i_min>
        <cmd_max>2.5</cmd_max>
        <cmd_min>-2.5</cmd_min>
        <jointName>rotor_2_joint</jointName>
        <multiplier>-838</multiplier>
        <controlVelocitySlowdownSim>1</controlVelocitySlowdownSim>
      </control>
      <control channel="3">
        <type>VELOCITY</type>
        <offset>0</offset>
        <p_gain>0.20</p_gain>
        <i_gain>0</i_gain>
        <d_gain>0</d_gain>
        <i_max>0</i_max>
        <i_min>0</i_min>
        <cmd_max>2.5</cmd_max>
        <cmd_min>-2.5</cmd_min>
        <jointName>rotor_3_joint</jointName>
        <multiplier>-838</multiplier>
        <controlVelocitySlowdownSim>1</controlVelocitySlowdownSim>
      </control>
    </plugin>
  </model>
</sdf>
